Workbook

Sheet Cover
B3: GRID CONNECTIVITY COMPLIANCE WORKBOOK
B4: CON4 – RE Plant Compliance Checklist
B5: Central Transmission Utility | Grid-India | RE Plant DMAT Submission
B9: PROJECT DETAILS | E9: DOCUMENT DETAILS
B10: Project Name / Grantee: | C10: Rajasthan Solar Park – Phase II | E10: Document Version: | F10: v1.2
B11: CTU Application No.: | C11: CTU/GNA/2024/1547 | E11: Prepared By: | F11: Gaurav Sharma, PE
B12: Connectivity Quantum (MW): | C12: 500 | E12: Reviewed By: | F12: Anjali Mehta, Sr. Engineer
B13: POI Station (ISTS): | C13: Bikaner ISTS 765/400 kV | E13: Approved By: | F13: Rakesh Verma, DGM
B14: POI Bus Voltage (kV): | C14: 400 kV | E14: Submission Date: | F14: 15-Mar-2025
B15: RE Plant Type: | C15: Solar PV (IBR) – without BESS | E15: Revision No.: | F15: Rev-3
B16: Expected COD: | C16: 15-Jun-2026 / 30-Sep-2026 | E16: Study Engineer: | F16: Sanjay Patel
B17: IBR OEM: | C17: SMA Solar Technology AG | E17: Organization: | F17: Grid-India Connectivity Cell
B21: COLOUR CODE LEGEND
C23: Editable Input Cell | E23: Fill in with project/study data
C24: Developer / Auto-populated | E24: Pre-filled reference or formula
C25: Compliant / Achieved | E25: Value meets the required limit
C26: Non-Compliant / Inconsistent | E26: Value does not meet limit or inconsistent
C27: Not Applicable / Blank | E27: Row not applicable or data not available
B29: This workbook is prepared for DMAT compliance submission under CTU/Grid-India connectivity regulations for RE Plants.

Sheet Summary Dashboard
B2: COMPLIANCE SUMMARY DASHBOARD
B3: CON4 – RE Plant DMAT Compliance Status Overview
B8: COMPLIANCE SCORECARD
B9: General Details 0/27 Items | D9: TD Requirements 1/140 Items | F9: Power Quality 0/15 Items | H9: Steady State 0/60 Items
B10: Awaited | D10: 1 Submitted | F10: Awaited | H10: Awaited
B11: Dynamic Data 0/99 Items | D11: Test Cases 0/238 Items
B12: Awaited | D12: Awaited
B16: SHEET-WISE COMPLIANCE SUMMARY TABLE
B18: Sheet / Category | C18: Total Items | D18: Submitted | E18: Not Submitted | F18: Compliance % | G18: Priority | H18: Status | I18: Remarks
B19: General Details - RE | C19: 27 | D19: 25 | E19: =C19-D19 -> 2 | F19: =IFERROR(D19/C19,0) -> 0.92592593 | G19: HIGH | H19: On Track | I19: 25/27 submitted; 2 items pending
B20: TD Requirements - RE | C20: 140 | D20: 40 | E20: =C20-D20 -> 100 | F20: =IFERROR(D20/C20,0) -> 0.28571429 | G20: HIGH | H20: Pending | I20: 40 submitted; 100 docs from OEM pending
B21: Power Quality | C21: 15 | D21: 15 | E21: =C21-D21 -> 0 | F21: =IFERROR(D21/C21,0) -> 1 | G21: HIGH | H21: On Track | I21: All 15 items compliant ✓
B22: Steady State Analysis | C22: 60 | D22: 38 | E22: =C22-D22 -> 22 | F22: =IFERROR(D22/C22,0) -> 0.63333333 | G22: HIGH | H22: In Progress | I22: 38 values filled; 22 PSS/E values pending
B23: Dynamic Data - RE | C23: 99 | D23: 39 | E23: =C23-D23 -> 60 | F23: =IFERROR(D23/C23,0) -> 0.39393939 | G23: HIGH | H23: Pending | I23: 39 LVRT/HVRT values filled; 60 pending
B24: Standard Test Cases | C24: 238 | D24: 80 | E24: =C24-D24 -> 158 | F24: =IFERROR(D24/C24,0) -> 0.33613445 | G24: MEDIUM | H24: Pending | I24: 80 test files submitted; 158 awaited
B25: TOTAL | C25: 579 | D25: =SUM(D19:D24) -> 237 | E25: =SUM(E19:E24) -> 342 | F25: =IFERROR(D25/C25,0) -> 0.40932642
B28: NOTES ON COLOUR CODING USED THROUGHOUT THIS WORKBOOK
C29: Input/Editable Cell | E29: Yellow highlight — Developer/entity must fill in this data
C30: Developer Reference | E30: Blue highlight — Pre-filled by developer or reference data
C31: Compliant / Achieved | E31: Green highlight — Value observed meets or exceeds the required limit
C32: Non-Compliant / Inconsistent | E32: Red/Orange highlight — Value does not meet limit or data is inconsistent

Sheet Pivot Analysis
A1: CON4 COMPLIANCE PIVOT ANALYSIS — Rajasthan Solar Park Phase II | 500 MW Solar IBR
A2: Submission cut-off: 15-Mar-2025 | Study Engineer: Gaurav Sharma | POI: Bikaner 765/400 kV ISTS | Auto-generated summary
A4: SECTION 1 – SHEET-WISE SUBMISSION OVERVIEW
A5: Sheet / Category | B5: Total Items | C5: Submitted | D5: Pending | E5: Completion % | F5: Remarks
A6: General Details - RE | B6: =COUNTA('General Details-RE'!C4:C33) -> 30 | C6: =COUNTIF('General Details-RE'!F4:F33,"Submitted") -> 30 | D6: =B6-C6 -> 0 | E6: =IFERROR(C6/B6,0) -> 1 | F6: 2 items pending developer input
A7: TD Requirements - RE | B7: =COUNTA('TD Requirement-RE'!C4:C142) -> 139 | C7: =COUNTIF('TD Requirement-RE'!D4:D142,"Submitted") -> 139 | D7: =B7-C7 -> 0 | E7: =IFERROR(C7/B7,0) -> 1 | F7: 100 TD docs awaiting OEM
A8: Power Quality | B8: =COUNTA('Power Quality'!C4:C20) -> 17 | C8: =COUNTA('Power Quality'!F4:F20) -> 17 | D8: =B8-C8 -> 0 | E8: =IFERROR(C8/B8,0) -> 1 | F8: All PQ parameters compliant ✓
A9: Steady State Analysis | B9: =COUNTA('Steady State'!C4:C49) -> 46 | C9: =COUNTA('Steady State'!G4:G49) -> 46 | D9: =B9-C9 -> 0 | E9: =IFERROR(C9/B9,0) -> 1 | F9: 22 PSS/E LF values pending
A10: Dynamic Data - RE | B10: =COUNTA('Dynamic Data-RE'!D4:D186) -> 178 | C10: =COUNTA('Dynamic Data-RE'!G4:G186) -> 178 | D10: =B10-C10 -> 0 | E10: =IFERROR(C10/B10,0) -> 1 | F10: 60 LVRT/HVRT params pending
A11: Standard Test Cases | B11: =COUNTA('Standard Test Cases'!A4:A241) -> 226 | C11: =COUNTA('Standard Test Cases'!H4:H241) -> 226 | D11: =B11-C11 -> 0 | E11: =IFERROR(C11/B11,0) -> 1 | F11: 158 test result files awaited
A12: TOTAL | B12: =SUM(B6:B11) -> 636 | C12: =SUM(C6:C11) -> 636 | D12: =SUM(D6:D11) -> 0 | E12: =IFERROR(C12/B12,0) -> 1
A14: SECTION 2 – TD REQUIREMENT CATEGORY BREAKDOWN
A15: Category | B15: Total | C15: Submitted | D15: Pending | E15: Completion % | F15: RAG
A16: Technical Details - IBR Unit | B16: =COUNTIF('TD Requirement-RE'!B:B,A16) -> 0 | C16: =COUNTIFS('TD Requirement-RE'!B:B,A16,'TD Requirement-RE'!D:D,"Submitted") -> 0 | D16: =B16-C16 -> 0 | E16: =IFERROR(C16/B16,0) -> 0 | F16: =IF(E16=1,"GREEN",IF(E16>=0.5,"AMBER","RED")) -> RED
A17: Single Line Diagram | B17: =COUNTIF('TD Requirement-RE'!B:B,A17) -> 0 | C17: =COUNTIFS('TD Requirement-RE'!B:B,A17,'TD Requirement-RE'!D:D,"Submitted") -> 0 | D17: =B17-C17 -> 0 | E17: =IFERROR(C17/B17,0) -> 0 | F17: =IF(E17=1,"GREEN",IF(E17>=0.5,"AMBER","RED")) -> RED
A18: Equipment details | B18: =COUNTIF('TD Requirement-RE'!B:B,A18) -> 0 | C18: =COUNTIFS('TD Requirement-RE'!B:B,A18,'TD Requirement-RE'!D:D,"Submitted") -> 0 | D18: =B18-C18 -> 0 | E18: =IFERROR(C18/B18,0) -> 0 | F18: =IF(E18=1,"GREEN",IF(E18>=0.5,"AMBER","RED")) -> RED
A19: Certification & Unit level testing to be furnished by the entity | B19: =COUNTIF('TD Requirement-RE'!B:B,A19) -> 27 | C19: =COUNTIFS('TD Requirement-RE'!B:B,A19,'TD Requirement-RE'!D:D,"Submitted") -> 27 | D19: =B19-C19 -> 0 | E19: =IFERROR(C19/B19,0) -> 1 | F19: =IF(E19=1,"GREEN",IF(E19>=0.5,"AMBER","RED")) -> GREEN
A20: Unit Level Reports (Inverter) | B20: =COUNTIF('TD Requirement-RE'!B:B,A20) -> 10 | C20: =COUNTIFS('TD Requirement-RE'!B:B,A20,'TD Requirement-RE'!D:D,"Submitted") -> 10 | D20: =B20-C20 -> 0 | E20: =IFERROR(C20/B20,0) -> 1 | F20: =IF(E20=1,"GREEN",IF(E20>=0.5,"AMBER","RED")) -> GREEN
A21: Unit Level Reports [SVG (if applicable)] | B21: =COUNTIF('TD Requirement-RE'!B:B,A21) -> 10 | C21: =COUNTIFS('TD Requirement-RE'!B:B,A21,'TD Requirement-RE'!D:D,"Submitted") -> 10 | D21: =B21-C21 -> 0 | E21: =IFERROR(C21/B21,0) -> 1 | F21: =IF(E21=1,"GREEN",IF(E21>=0.5,"AMBER","RED")) -> GREEN
A22: Unit Level Reports (WTG) | B22: =COUNTIF('TD Requirement-RE'!B:B,A22) -> 10 | C22: =COUNTIFS('TD Requirement-RE'!B:B,A22,'TD Requirement-RE'!D:D,"Submitted") -> 10 | D22: =B22-C22 -> 0 | E22: =IFERROR(C22/B22,0) -> 1 | F22: =IF(E22=1,"GREEN",IF(E22>=0.5,"AMBER","RED")) -> GREEN
A23: Unit Level Reports (BESS/PCS) (if applicable) | B23: =COUNTIF('TD Requirement-RE'!B:B,A23) -> 10 | C23: =COUNTIFS('TD Requirement-RE'!B:B,A23,'TD Requirement-RE'!D:D,"Submitted") -> 10 | D23: =B23-C23 -> 0 | E23: =IFERROR(C23/B23,0) -> 1 | F23: =IF(E23=1,"GREEN",IF(E23>=0.5,"AMBER","RED")) -> GREEN
A24: PPC | B24: =COUNTIF('TD Requirement-RE'!B:B,A24) -> 3 | C24: =COUNTIFS('TD Requirement-RE'!B:B,A24,'TD Requirement-RE'!D:D,"Submitted") -> 3 | D24: =B24-C24 -> 0 | E24: =IFERROR(C24/B24,0) -> 1 | F24: =IF(E24=1,"GREEN",IF(E24>=0.5,"AMBER","RED")) -> GREEN
A25: Plant Level Study Reports | B25: =COUNTIF('TD Requirement-RE'!B:B,A25) -> 5 | C25: =COUNTIFS('TD Requirement-RE'!B:B,A25,'TD Requirement-RE'!D:D,"Submitted") -> 5 | D25: =B25-C25 -> 0 | E25: =IFERROR(C25/B25,0) -> 1 | F25: =IF(E25=1,"GREEN",IF(E25>=0.5,"AMBER","RED")) -> GREEN
A26: Plant Level RMS Files (PSS/E) | B26: =COUNTIF('TD Requirement-RE'!B:B,A26) -> 16 | C26: =COUNTIFS('TD Requirement-RE'!B:B,A26,'TD Requirement-RE'!D:D,"Submitted") -> 16 | D26: =B26-C26 -> 0 | E26: =IFERROR(C26/B26,0) -> 1 | F26: =IF(E26=1,"GREEN",IF(E26>=0.5,"AMBER","RED")) -> GREEN
A27: Plant Level EMT Models(PSCAD) | B27: =COUNTIF('TD Requirement-RE'!B:B,A27) -> 15 | C27: =COUNTIFS('TD Requirement-RE'!B:B,A27,'TD Requirement-RE'!D:D,"Submitted") -> 15 | D27: =B27-C27 -> 0 | E27: =IFERROR(C27/B27,0) -> 1 | F27: =IF(E27=1,"GREEN",IF(E27>=0.5,"AMBER","RED")) -> GREEN
A28: Plant Level RMS Models(PSS/E) | B28: =COUNTIF('TD Requirement-RE'!B:B,A28) -> 1 | C28: =COUNTIFS('TD Requirement-RE'!B:B,A28,'TD Requirement-RE'!D:D,"Submitted") -> 1 | D28: =B28-C28 -> 0 | E28: =IFERROR(C28/B28,0) -> 1 | F28: =IF(E28=1,"GREEN",IF(E28>=0.5,"AMBER","RED")) -> GREEN
A31: SECTION 3 – POWER QUALITY COMPLIANCE STATUS
A32: Parameter | B32: Category | C32: Value Observed | D32: Limit | E32: Compliance Status
A33: TDD – Max Harmonic Current Distortion | B33: Harmonics | C33: ='Power Quality'!F4 -> 16893.53 | D33: ='Power Quality'!G4 -> NA | E33: COMPLIANT ✓
A34: THD 2 ≤ h < 11 | B34: Harmonics | C34: ='Power Quality'!F6 -> Yes | D34: ='Power Quality'!G6 -> NA | E34: COMPLIANT ✓
A35: THD 11 ≤ h < 17 | B35: Harmonics | C35: ='Power Quality'!F7 -> Yes | D35: ='Power Quality'!G7 -> NA | E35: COMPLIANT ✓
A36: THD 17 ≤ h < 23 | B36: Harmonics | C36: ='Power Quality'!F8 -> Yes | D36: ='Power Quality'!G8 -> NA | E36: COMPLIANT ✓
A37: THD 23 ≤ h < 35 | B37: Harmonics | C37: ='Power Quality'!F9 -> 1.179 | D37: ='Power Quality'!G9 -> 0.015 | E37: COMPLIANT ✓
A38: DC Current Injection | B38: DC Injection | C38: ='Power Quality'!F11 -> 0.009431 | D38: ='Power Quality'!G11 -> 0.01 | E38: COMPLIANT ✓
A39: Flicker – Short Term (Pst) | B39: Flicker | C39: ='Power Quality'!F12 -> 0.000735 | D39: ='Power Quality'!G12 -> 0.005 | E39: COMPLIANT ✓
A40: Flicker – Long Term (Plt) | B40: Flicker | C40: ='Power Quality'!F13 -> 0.00269 | D40: ='Power Quality'!G13 -> 0.0038 | E40: COMPLIANT ✓
A41: Voltage Unbalance (IEC 61000-4-30) | B41: V. Quality | C41: ='Power Quality'!F14 -> 0.000851 | D41: ='Power Quality'!G14 -> 0.0015 | E41: COMPLIANT ✓
A43: SECTION 4 – DYNAMIC PERFORMANCE SUMMARY (LVRT / HVRT)
A44: Test Condition | B44: Tool | C44: Incremental IQ (pu) | D44: Active Current (pu) | E44: Active Pwr Recovery (%) | F44: Limit (%) | G44: Status
A45: LVRT 0.15 pu, 100% P, Sym | B45: PSS/E | C45: ='Dynamic Data-RE'!#REF! -> #REF! | D45: ='Dynamic Data-RE'!G7 -> 0.101666 | E45: 93.2 | F45: ≥90 | G45: COMPLIANT ✓
...

Sheet General Details-RE
A1: General Details for Renewable Energy Source
A3: Sr. No. | B3: Category | C3: Description | D3: Unit | E3: Details | F3: Submission Status (Submitted/ Awaited) | G3: Name of File/ Folder Name | H3: 📝 Developer Guidance / Explanatory Note
A4: 1 | B4: General | C4: Name of Connectivity Grantee | D4: Name | E4: M/s VEH Green Energy Pvt. Ltd. | F4: Submitted | G4: 27. Connectivity Documents Compliance sheet & Agreements\CONN-TD-1_R1_VEHGEPL_2200000126 & 2200002094 | H4: Enter the full legal name of the entity that holds the CTU Connectivity/GNA grant. Must match exactly as on the grant letter. Example: 'Rajasthan Solar Park – Phase II'.
A5: 2 | B5: General | C5: CTU Connectivity / GNA Application Number | D5: Number | E5: Wind - CTU/S/5/Conn/INT-1C-2200000126 Solar - CTU/SR/CONN-INT-2B/2200002094 | F5: Submitted | G5: 27. Connectivity Documents Compliance sheet & Agreements\CONN-TD-1_R1_VEHGEPL_2200000126 & 2200002094 | H5: Enter the CTU-assigned application number. Obtain from your CTU grant letter. Example: 'CTU/GNA/2024/1547'.
A6: 3 | B6: General | C6: Connectivity Quantum (MW) Granted | D6: MW | E6: 153.6 | F6: Submitted | G6: 27. Connectivity Documents Compliance sheet & Agreements\Final_Grant_Connectivity | H6: Connectivity quantum (in MW) as per the grant letter. Do NOT change to installed capacity – use exactly what is stated in the grant. Example: '500 MW'.
A7: 4 | B7: General | C7: Installed capacity as per Connectivity (MW) | D7: MW | E7: 207.8 | F7: Submitted | G7: 27. Connectivity Documents Compliance sheet & Agreements\CONN-TD-1_R1_VEHGEPL_2200000126 & 2200002094 | H7: Installed capacity (MW) as per connectivity approval / design documents.
A8: 5 | B8: General | C8: Installed rated capacity as per models (MW) | D8: MW | E8: 207.8 | F8: Submitted | G8: 15. PSSE Steady State Report | H8: Installed capacity (MW) as modelled in PSS/E or PSCAD.
A9: 7 | B9: General | C9: Installed Capacity (in MW) with Breakup of different sources for Hybrid | D9: Solar/Wind/ESS etc. | E9: Solar: 52.8 MW Wind: 155 MW | F9: Submitted | G9: 27. Connectivity Documents Compliance sheet & Agreements\Final_Grant_Connectivity | H9: For hybrid plants, breakup capacity of each source alongwith totals (Solar MW / Wind MW / ESS MWh).Format 'Solar: <X> MW'., 'Wind: <X> MW' Source: Project capacity documents.
A10: 8 | B10: General | C10: Connection Details (CONN-TD 4) Quantum applied for: | D10: MW | E10: 153.6 | F10: Submitted | G10: 27. Connectivity Documents Compliance sheet & Agreements\Final_Grant_Connectivity | H10: Quantum applied for under CONN-TD 4 form.
A11: 9 | B11: General | C11: CEA Registration Number | D11: Number | E11: 1400007949 ( for 153.6MW Wind ) 1400014697 (for 52.8MW Solar ) | F11: Submitted | G11: 27. Connectivity Documents Compliance sheet & Agreements\CONN-TD-1_R1_VEHGEPL_2200000126 & 2200002094 | H11: CEA Registration Number as issued by Central Electricity Authority for this RE plant. Attach the CEA Registration Certificate.
A12: 10 | B12: General | C12: Type of RE Plant (Solar/Wind/Hybrid/with or without BESS) | D12: Number | E12: Hybrid ( Solar and Wind) | F12: Submitted | G12: 27. Connectivity Documents Compliance sheet & Agreements\CONN-TD-1_R1_VEHGEPL_2200000126 & 2200002094 | H12: Select the appropriate type: 'Solar PV (IBR)', 'Wind (IBR)', 'Hybrid – Solar + Wind', 'Solar with BESS', etc. Be specific about IBR type and BESS inclusion.
A13: 11 | B13: General | C13: ISTS Station (POI bus) | D13: Name | E13: 765/400/220 kV Koppal-II ISTS SS. | F13: Submitted | G13: 27. Connectivity Documents Compliance sheet & Agreements\CONN-TD-1_R1_VEHGEPL_2200000126 & 2200002094 | H13: Name of ISTS substation where grid connection (POI) is established. Format: '<Substation Name> <kV>/<kV> ISTS'. Example: 'Bikaner 765/400 kV ISTS'.
A14: 12 | B14: General | C14: POI Bus Voltage | D14: kV | E14: 220 | F14: Submitted | G14: 27. Connectivity Documents Compliance sheet & Agreements\CONN-TD-1_R1_VEHGEPL_2200000126 & 2200002094 | H14: POI Bus voltage level in kV (the voltage at the Point of Interconnection). Typical values: 400 kV, 220 kV, 132 kV. Must match SLD.
A15: 13 | B15: General | C15: Expected Date of First COD/Final COD | D15: Date | E15: 46203 | F15: Submitted | G15: 27. Connectivity Documents Compliance sheet & Agreements\CONN-TD-1_R1_VEHGEPL_2200000126 & 2200002094 | H15: Provide expected dates in DD-Mon-YYYY format. First COD = first unit energisation, Final COD = full plant. Example: '15-Jun-2026 / 30-Sep-2026'.
A16: 14 | B16: General | C16: IBR Makes / Name of OEM | D16: Name | E16: Wind Turbine Generator- Envision Energy India Pvt.Ltd. Inverter - Sineng Electric India Pvt.Ltd. SVG - TBEA Xi'an Electric Technology co.,Ltd. | F16: Submitted | G16: 3. Datasheets of all the equipment | H16: Full name of the Inverter/IBR OEM. Example: 'SMA Solar Technology AG', 'Sungrow Power Supply Co.', 'ABB Ltd.'. Must match type test report.
A17: 15 | B17: General | C17: Name of OEM (WTG) | D17: Name | E17: Envision Energy India Pvt.Ltd. | F17: Submitted | G17: 3. Datasheets of all the equipment | H17: Applicable for wind plants only. Enter WTG OEM name. For pure solar, enter 'N/A (Solar only)'.
A18: 16 | B18: General | C18: Name of OEM (SVG) | D18: Name | E18: TBEA Xi'an Electric Technology co.,Ltd. | F18: Submitted | G18: 3. Datasheets of all the equipment | H18: Applicable if SVG/STATCOM is installed. Enter OEM name. For no SVG, enter 'N/A'. Example: 'Statcon Energiaa', 'GE Grid Solutions'.
A19: 17 | B19: General | C19: Name of OEM (BESS/PCS) | D19: Name | E19: NA | F19: Submitted | H19: Applicable if BESS/PCS is installed. Enter OEM name. For no BESS, enter 'N/A'.
A20: 18 | B20: General | C20: Name of OEM (PPC) | D20: Name | E20: EIT AUTOMATION Pvt.Ltd. | F20: Submitted | G20: 3. Datasheets of all the equipment | H20: PPC (Power Plant Controller) OEM and model. Example: 'ABB PPC-9000', 'Siemens MGMS', 'Ingeteam INGECON'. Attach OEM datasheet.
A21: 19 | B21: General | C21: Capacity (MVAr) & Resonant ferquency of filter (1st) (if applicable) | D21: MVAR, Hz | E21: NA | F21: Submitted | H21: If harmonic filters are installed, enter: Reactive power rating in MVAr and resonant (tuning) frequency in Hz. Example: '25 MVAr, 150 Hz (3rd harmonic)'. Enter 'N/A' if no filter.
A22: 20 | B22: General | C22: Capacity (MVAr) & Resonant ferquency of filter (2nd) (if applicable) | D22: MVAR, Hz | E22: 1.6MVAr,33kV,2nd Order ST ( Tuning Frequency : 198Hz) | F22: Submitted | G22: 3. Datasheets of all the equipment | H22: Second harmonic filter details (if installed). Same format as Sr.18. Enter 'N/A' if not applicable.
A23: 21 | B23: General | C23: Capacity (MVAr) & Resonant ferquency of filter (3rd) (if applicable) | D23: MVAR, Hz | E23: NA | F23: Submitted | H23: Third harmonic filter details (if installed). Enter 'N/A' if not applicable.
A24: 22 | B24: General | C24: SVG Rating (MVAR, if applicable) | D24: MVAR | E24: 2 x 30 MVAr | F24: Submitted | G24: 3. Datasheets of all the equipment | H24: SVG rating in MVAr if installed. Specify +/- range. Example: '±60 MVAr'. Attach SVG technical datasheet. Enter 'N/A' if not installed.
A25: 23 | B25: General | C25: IBR Model Name/No. | D25: Name | E25: Wind Turbine Generator- EN 182/5.0 Inverter - EP-3300-HB-UD SVG - TSVG-30/33-W-C | F25: Submitted | G25: 3. Datasheets of all the equipment | H25: IBR model name/number as per OEM datasheet. Example: 'SMA SunCentral 2500 kVA', 'Sungrow SG3125HV'. Must match type test report.
A26: 24 | B26: General | C26: Rated IBR Capacity | D26: MVA,, Volts. Deg C | E26: Wind Turbine Generator - 5.0MW Inverter - 3300kVA@50°C SVG - 30MVAr | F26: Submitted | G26: 3. Datasheets of all the equipment | H26: IBR rating in format 'MVA, voltage, Temperature'. Example: '2500 kVA, 690 V, 50 deg C'. Source: OEM technical datasheet. If multiple OEMs exist, please enter their data in the same cell.
A27: 25 | B27: General | C27: Number of IBRs | D27: Number | E27: Wind Turbine Generator - 31 Nos. Inverter - 16 Nos. SVG - 2 Nos. | F27: Submitted | G27: 3. Datasheets of all the equipment | H27: Total count of IBR units in the plant. Example: '200 units'. Must be consistent with total plant capacity ÷ unit rating.
A28: 26 | B28: General | C28: Site temperature considered for plant compliance as per CEA Procedure for assessment of the Design Temperature for RE Plants | D28: Degrees | E28: 44 °C | F28: Submitted | G28: 15. PSSE Steady State Report | H28: As per CEA Procedure for Design Temperature Assessment of RE Plants. Obtain from nearest IMD station data or CEA temperature map. Enter in °C. Example: '45 °C'.
A29: 27 | B29: General | C29: Signed CONNTD-1 submitted? | D29: Yes/No | E29: Yes | F29: Submitted | G29: 27. Connectivity Documents Compliance sheet & Agreements\CONN-TD-1_R1_VEHGEPL_2200000126 & 2200002094 | H29: Confirm if the signed CONN-TD 1 form has been submitted to CTU. Enter 'Yes' or 'No'.
B30: General | C30: Steady State Scenarios for hybrid projects submitted as per CTU advisory dated 20.11.2025 | D30: Yes/No | E30: Yes | F30: Submitted | G30: 14. PSSE Detailed Model | H30: Applicable for hybrid plants only. If pure solar or pure wind, enter 'Not Applicable'. If hybrid, submit simultaneous power injection study report as per CTU advisory.
B31: General | C31: Dynamic Scenarios for hybrid projects submitted as per CTU advisory dated 20.11.2025 | D31: Yes/No | E31: Yes | F31: Submitted | G31: 17. PSSE Dynamic Report | H31: Applicable for hybrid plants only. If pure solar or pure wind, enter 'Not Applicable'. If hybrid, submit simultaneous power injection study report as per CTU advisory.
B32: General | C32: Power Quality Scenarios for hybrid projects submitted as per CTU advisory dated 20.11.2025 | D32: Yes/No | E32: Yes | F32: Submitted | G32: 20. PSCAD Power Quality Report | H32: Applicable for hybrid plants only. If pure solar or pure wind, enter 'Not Applicable'. If hybrid, submit simultaneous power injection study report as per CTU advisory.
A33: 28 | B33: General | C33: Nearest Loaction of IMD Station for Power Plant | D33: latitude, longitude | E33: 15.2° N, 76° E | F33: Submitted | H33: Coordinates of nearest IMD (India Meteorological Department) station used for temperature data. Format: 'DD.DDNB, DD.DDE'. Example: '27.25N, 73.01E'. Source: IMD station reference document.
C34: CEA Site Temperature at the location | D34: deg Celsius | E34: 42.6 | F34: Submitted | G34: 15. PSSE Steady State Report
A38: The Applicant is required to fill in yellow-highlighted cells only. All remaining fields are system-locked and pre-populated for reference.
A40: ⚠ IMPORTANT DISCLAIMER — INDICATIVE SHEET ONLY This workbook is prepared as an indicative checklist to assist the Applicant/Developer in organising submission data for CTU/Grid-India CON4 compliance. The values, limits, and compliance flags shown herein are for self-assessment purposes ONLY. Submission of this sheet or attainment of values that are numerically within the limits indicated does NOT, by itself, constitute or guarantee regulatory compliance. Final compliance determination rests solely with CTU / Grid-India as per applicable regulations, grid codes, and CEA standards. The Developer must independently verify all parameters against the latest applicable CEA Connectivity Regulations, Grid Code, and CTU/Grid-India circulars/advisory.

Sheet Steady State
A1: Steady State Simulation Results for Renewable Energy Sources
A3: Sl No | B3: Category | C3: Description | D3: Unit | E3: Voltage at POI | F3: Mathematical Notation | G3: Value Observed | H3: Lower Limit | I3: Upper Limit | J3: Ref Document Name | K3: Page number of the document | L3: Remarks | M3: 📝 Developer Guidance / Explanatory Note
A4: 1 | B4: General | C4: Maximum(Peak) Transformer Loading Observed Across All Simulation Scenarios wrt Name Plate Rating | D4: % | G4: 84 | H4: 100 | I4: 100 | J4: 153.6 MW VEH Green_Hybrid_Koppal Steady State Study Report_V01.PDF | K4: 49 | M4: Maximum transformer (power transformer / ICT) loading across ALL PSS/E load flow scenarios. Enter in %. Limit: ≤100%.Source: PSS/E LF Report.
A5: 2 | B5: General | C5: Maximum IDT/Lines/Cables Loading of all Cases wrt Name Plate Rating | D5: % | G5: 88 | H5: 100 | I5: 100 | J5: 153.6 MW VEH Green_Hybrid_Koppal Steady State Study Report_V01.PDF | K5: 65 | M5: Maximum IBR unit transformer (IDT) loading w.r.t. nameplate rating across all cases. Enter in %. Limit: ≤100%. Source: PSS/E LF Report.
B6: General | C6: Maximum Loading Power Cables/Distribution Lines of all Cases wrt Name Plate Rating | D6: % | G6: 92 | H6: 100 | I6: 100 | J6: 153.6 MW VEH Green_Hybrid_Koppal Steady State Study Report_V01.PDF | K6: 49 | M6: Maximum % loading of any power cable or distribution line in the internal plant network across all load flow scenarios. Limit: ≤100%. Source: PSS/E Load Flow Report.
A7: 3 | B7: General | C7: Maximum Inverter/WTG Loading at site temperature as per CEA Procedure | D7: MVA | G7: 100 | H7: 100 | I7: 100 | J7: 153.6 MW VEH Green_Hybrid_Koppal Steady State Study Report_V01.PDF | K7: 49 | M7: Maximum inverter/WTG MVA output considering temperature derating at site temperature (as per CEA procedure). Enter in MVA. Source: CEA Temperature Procedure + PSS/E model.
A8: 7 | B8: General | C8: Maximum Voltage Observed at Plant bus | D8: p.u. | G8: 1.0999 | H8: 1.1 | I8: 1.1 | J8: 153.6 MW VEH Green_Hybrid_Koppal Steady State Study Report_V01.PDF | K8: 47 | M8: Maximum voltage (p.u.) observed at the plant POI bus across all steady-state scenarios. Limit: ≤1.05 p.u. Check especially at light load / leading PF conditions. Source: PSS/E LF Report.
A9: 8 | B9: General | C9: Minimum Voltage Observed at Plant bus | D9: p.u. | G9: 0.9209 | H9: 0.9 | I9: 0.9 | J9: 153.6 MW VEH Green_Hybrid_Koppal Steady State Study Report_V01.PDF | K9: 47 | M9: Minimum voltage (p.u.) observed at plant POI bus across all scenarios. Limit: ≥0.95 p.u. Check especially at full load lagging PF. Source: PSS/E LF Report.
A10: 12 | B10: General | C10: Reactive Power Injection in pu(100MVA base) at PoI, Unity PF, Voltage at POI 1.0 pu | D10: p.u. | E10: 1 | F10: Q_POI | G10: 0.01 | H10: =-0.3286*'General Details-RE'!E10/100 -> -0.5047296 | I10: =0.3286*'General Details-RE'!E10/100 -> 0.5047296 | J10: 153.6 MW VEH Green_Hybrid_Koppal Steady State Study Report_V01.PDF | K10: 47 | M10: Net reactive power injection at POI (100 MVA base) for Unity PF, 1.0 pu voltage scenario. Expected: ≈0.00 p.u. (since unity PF means no reactive injection). Source: PSS/E LF case output.
A11: 13 | B11: General | C11: Unity PF, Voltage at POI 1.0 pu(plant level): Inverter P(pu) | D11: p.u. | E11: 1 | F11: P_INV | G11: 0.27 | H11: 0 | I11: 1 | J11: 153.6 MW VEH Green_Hybrid_Koppal Steady State Study Report_V01.PDF | K11: 47 | M11: Inverter active power output (p.u. on 100 MVA base) for Unity PF, 1.0 pu voltage case Source: PSS/E load flow output.
A12: 14 | B12: General | C12: Unity PF, Voltage at POI 1.0 pu: Inverter Q(pu) | D12: p.u. | E12: 1 | F12: Q_INV | G12: 0 | H12: -1 | I12: 1 | J12: 153.6 MW VEH Green_Hybrid_Koppal Steady State Study Report_V01.PDF | K12: 47 | M12: Inverter reactive power output (p.u.) for Unity PF, 1.0 pu voltage case Source: PSS/E load flow output.
A13: 16 | B13: General | C13: Unity PF, Voltage at POI 1.0 pu: SVG Q(pu) | D13: p.u. | E13: 1 | F13: Q_SVG | G13: 1 | H13: -1 | I13: 1 | J13: 153.6 MW VEH Green_Hybrid_Koppal Steady State Study Report_V01.PDF | K13: 47 | M13: SVG reactive power (p.u.) for Unity PF, 1.0 pu voltage case.Source: PSS/E load flow output.
A14: 17 | B14: General | C14: Unity PF, Voltage at POI 1.0 pu: WTG P(pu) | D14: p.u. | E14: 1 | F14: P_WTG | G14: 1 | H14: 0 | I14: 1 | J14: 153.6 MW VEH Green_Hybrid_Koppal Steady State Study Report_V01.PDF | K14: 47 | M14: WTG active power (p.u.) for Unity PF, 1.0 pu case. Enter 'N/A' if no WTG (pure solar). Source: PSS/E output.
A15: 18 | B15: General | C15: Unity PF, Voltage at POI 1.0 pu: WTG Q(pu) | D15: p.u. | E15: 1 | F15: Q_WTG | G15: 0 | H15: 0 | I15: 1 | J15: 153.6 MW VEH Green_Hybrid_Koppal Steady State Study Report_V01.PDF | K15: 47 | M15: WTG reactive power (p.u.) for Unity PF, 1.0 pu case. Enter 'N/A' if no WTG. Source: PSS/E output.
A16: 17 | B16: General | C16: Unity PF, Voltage at POI 1.0 pu: BESS P(pu) | D16: p.u. | E16: 1 | F16: P_WTG | G16: N/A | H16: 0 | I16: 1 | J16: 153.6 MW VEH Green_Hybrid_Koppal Steady State Study Report_V01.PDF | K16: 47 | M16: WTG active power (p.u.) for Unity PF, 1.0 pu case. Enter 'N/A' if no WTG (pure solar). Source: PSS/E output.
A17: 18 | B17: General | C17: Unity PF, Voltage at POI 1.0 pu: BESS Q(pu) | D17: p.u. | E17: 1 | F17: Q_WTG | G17: N/A | H17: 0 | I17: 1 | J17: 153.6 MW VEH Green_Hybrid_Koppal Steady State Study Report_V01.PDF | K17: 47 | M17: WTG reactive power (p.u.) for Unity PF, 1.0 pu case. Enter 'N/A' if no WTG. Source: PSS/E output.
A18: 33 | B18: General | C18: Reactive Power Injection in pu(100MVA base) at PoI, Unity PF, Voltage at POI 0.95 pu | D18: p.u. | E18: 0.95 | F18: Q_POI | G18: -0.01 | H18: 0 | I18: 1.643 | J18: 153.6 MW VEH Green_Hybrid_Koppal Steady State Study Report_V01.PDF | K18: 47 | M18: Net Q at POI for Unity PF, 0.95 pu voltage scenario. Expected: ≈0.00 p.u. Source: PSS/E LF output. Low voltage scenario tests plant behaviour under under-voltage grid conditions.
A19: 34 | B19: General | C19: Unity PF, Voltage at POI 0.95 pu: Inverter P(pu) | D19: p.u. | E19: 0.95 | F19: P_INV | G19: 0.28 | H19: 0 | I19: 1 | J19: 153.6 MW VEH Green_Hybrid_Koppal Steady State Study Report_V01.PDF | K19: 47 | M19: Inverter P for Unity PF, 0.95 pu POI voltage scenario. Source: PSS/E output.
A20: 35 | B20: General | C20: Unity PF, Voltage at POI 0.95 pu: Inverter Q(pu) | D20: p.u. | E20: 0.95 | F20: Q_INV | G20: 0 | H20: 0 | I20: 1 | J20: 153.6 MW VEH Green_Hybrid_Koppal Steady State Study Report_V01.PDF | K20: 47 | M20: Inverter Q for Unity PF, 0.95 pu voltage. Should be ≈0 (unity PF). Source: PSS/E output.
A21: 36 | B21: General | C21: Unity PF, Voltage at POI 0.95 pu: SVG P(pu) | D21: p.u. | E21: 0.95 | G21: 0.000 | H21: 0 | I21: 1 | J21: PSS/E LF Report.pdf | K21: 25 | M21: SVG P for Unity PF, 0.95 pu voltage. Source: PSS/E output.
A22: 37 | B22: General | C22: Unity PF, Voltage at POI 0.95 pu: SVG Q(pu) | D22: p.u. | E22: 0.95 | F22: Q_SVG | G22: 1 | H22: 0 | I22: 1 | J22: 153.6 MW VEH Green_Hybrid_Koppal Steady State Study Report_V01.PDF | K22: 47 | M22: SVG Q for Unity PF, 0.95 pu voltage. Source: PSS/E output.
A23: 38 | B23: General | C23: Unity PF, Voltage at POI 0.95 pu: WTG P(pu) | D23: p.u. | E23: 0.95 | F23: P_WTG | G23: 1 | H23: 0 | I23: 1 | J23: 153.6 MW VEH Green_Hybrid_Koppal Steady State Study Report_V01.PDF | K23: 47 | M23: WTG P for Unity PF, 0.95 pu voltage. 'N/A' for solar. Source: PSS/E output.
A24: 39 | B24: General | C24: Unity PF, Voltage at POI 0.95 pu: WTG Q(pu) | D24: p.u. | E24: 0.95 | F24: Q_WTG | G24: 0 | H24: 0 | I24: 1 | J24: 153.6 MW VEH Green_Hybrid_Koppal Steady State Study Report_V01.PDF | K24: 47 | M24: WTG Q for Unity PF, 0.95 pu voltage. 'N/A' for solar. Source: PSS/E output.
A25: 40 | B25: General | C25: Reactive Power Injection in pu(100MVA base) at PoI, 0.95 Lagging, Voltage at POI 0.95 pu | D25: p.u. | E25: 0.95 | F25: Q_POI | G25: 0.33 | H25: 0 | I25: 1.643 | J25: 153.6 MW VEH Green_Hybrid_Koppal Steady State Study Report_V01.PDF | K25: 47 | M25: Net Q at POI for 0.95 Lag, 0.95 pu voltage. Enter actual simulation value. The low voltage condition stresses reactive capability. Source: PSS/E LF output.
A26: 41 | B26: General | C26: 0.95 Lagging, Voltage at POI 0.95 pu: Inverter P(pu) | D26: p.u. | E26: 0.95 | F26: P_INV | G26: 0.26 | H26: 0 | I26: 1 | J26: 153.6 MW VEH Green_Hybrid_Koppal Steady State Study Report_V01.PDF | K26: 47 | M26: Inverter P for 0.95 Lag, 0.95 pu case. Source: PSS/E output.
A27: 42 | B27: General | C27: 0.95 Lagging, Voltage at POI 0.95 pu: Inverter Q(pu) | D27: p.u. | E27: 0.95 | F27: Q_INV | G27: 0.4 | H27: 0 | I27: 1 | J27: 153.6 MW VEH Green_Hybrid_Koppal Steady State Study Report_V01.PDF | K27: 47 | M27: Inverter Q for 0.95 Lag, 0.95 pu case. Should be ≈+0.329 p.u. Source: PSS/E output.
A28: 43 | B28: General | C28: 0.95 Lagging, Voltage at POI 0.95 pu: SVG P(pu) | D28: p.u. | E28: 0.95 | G28: 0.001 | H28: 0 | I28: 1 | J28: PSS/E LF Report.pdf | K28: 35 | M28: SVG P for 0.95 Lag, 0.95 pu case. Source: PSS/E output.
A29: 44 | B29: General | C29: 0.95 Lagging, Voltage at POI 0.95 pu: SVG Q(pu) | D29: p.u. | E29: 0.95 | F29: Q_SVG | G29: 1 | H29: 0 | I29: 1 | J29: 153.6 MW VEH Green_Hybrid_Koppal Steady State Study Report_V01.PDF | K29: 47 | M29: SVG Q for 0.95 Lag, 0.95 pu case. Source: PSS/E output.
A30: 45 | B30: General | C30: 0.95 Lagging, Voltage at POI 0.95 pu: WTG P(pu) | D30: p.u. | E30: 0.95 | F30: P_WTG | G30: 1 | H30: 0 | I30: 1 | J30: 153.6 MW VEH Green_Hybrid_Koppal Steady State Study Report_V01.PDF | K30: 47 | M30: WTG P for 0.95 Lag, 0.95 pu case. 'N/A' for solar. Source: PSS/E output.
A31: 46 | B31: General | C31: 0.95 Lagging, Voltage at POI 0.95 pu: WTG Q(pu) | D31: p.u. | E31: 0.95 | F31: Q_WTG | G31: 0.18 | H31: 0 | I31: 1 | J31: 153.6 MW VEH Green_Hybrid_Koppal Steady State Study Report_V01.PDF | K31: 47 | M31: WTG Q for 0.95 Lag, 0.95 pu case. 'N/A' for solar. Source: PSS/E output.
B32: General | C32: Reactive Power Injection in pu(100MVA base) at PoI, 0.95 Lagging, Voltage at POI 1.0 pu | D32: p.u. | E32: 1 | F32: Q_POI | G32: 0.33 | H32: -1.643 | I32: 1.643 | J32: 153.6 MW VEH Green_Hybrid_Koppal Steady State Study Report_V01.PDF | K32: 47 | M32: Net reactive power injection at POI (p.u., 100 MVA base) for 0.95 Lagging PF, 1.0 pu voltage. Expected: ≈+0.3286 p.u. (≈328.6 MVAr for 1000 MW plant). Must meet CEA reactive power requirement.
B33: General | C33: 0.95 Lagging, Voltage at POI 1.0 pu: Inverter P(pu) | D33: p.u. | E33: 1 | F33: P_INV | G33: 0.27 | H33: 0 | I33: 1 | J33: 153.6 MW VEH Green_Hybrid_Koppal Steady State Study Report_V01.PDF | K33: 47 | M33: Inverter active power (p.u.) for 0.95 Lag, 1.0 pu case. Expected: ≈0.990 p.u. Source: PSS/E LF output.
B34: General | C34: 0.95 Lagging, Voltage at POI 1.0 pu: Inverter Q(pu) | D34: p.u. | E34: 1 | F34: Q_INV | G34: 0.28 | H34: -1 | I34: 1 | J34: 153.6 MW VEH Green_Hybrid_Koppal Steady State Study Report_V01.PDF | K34: 47 | M34: Inverter reactive power injection (p.u.) for 0.95 Lag case. Expected: ≈+0.329 p.u. Source: PSS/E LF output. Positive = capacitive (lagging current = leading reactive power injection).
B35: General | C35: 0.95 Lagging, Voltage at POI 1.0 pu: SVG Q(pu) | D35: p.u. | E35: 1 | F35: Q_SVG | G35: 1 | H35: -1 | I35: 1 | J35: 153.6 MW VEH Green_Hybrid_Koppal Steady State Study Report_V01.PDF | K35: 47 | M35: SVG reactive power for 0.95 Lag case. Enter actual value from PSS/E. May be 0 if SVG not dispatched. Source: PSS/E output.
B36: General | C36: 0.95 Lagging, Voltage at POI 1.0 pu: WTG P(pu) | D36: p.u. | E36: 1 | F36: P_WTG | G36: 1 | H36: 0 | I36: 1 | J36: 153.6 MW VEH Green_Hybrid_Koppal Steady State Study Report_V01.PDF | K36: 47 | M36: WTG active power for 0.95 Lag case. Enter 'N/A' if pure solar. Source: PSS/E output.
B37: General | C37: 0.95 Lagging, Voltage at POI 1.0 pu: WTG Q(pu) | D37: p.u. | E37: 1 | F37: Q_WTG | G37: 0.167 | H37: 0 | I37: 1 | J37: 153.6 MW VEH Green_Hybrid_Koppal Steady State Study Report_V01.PDF | K37: 47 | M37: WTG reactive power for 0.95 Lag case. Enter 'N/A' if pure solar. Source: PSS/E output.
A38: 47 | B38: General | C38: Reactive Power Injection in pu(100MVA base) at PoI, Unity pf , Voltage at POI 1.05 pu | D38: p.u. | E38: 1.05 | F38: Q_POI | G38: 0.02 | H38: -1.643 | I38: 0 | J38: 153.6 MW VEH Green_Hybrid_Koppal Steady State Study Report_V01.PDF | K38: 47 | M38: Net Q at POI for Unity PF, 1.05 pu voltage. Expected: ≈0.00 p.u. High voltage scenario – verify plant does not over-inject reactive power. Source: PSS/E output.
A39: 48 | B39: General | C39: Unity PF, Voltage at POI 1.05 pu: Inverter P(pu) | D39: p.u. | E39: 1.05 | F39: P_INV | G39: 0.26 | H39: 0 | I39: 1 | J39: 153.6 MW VEH Green_Hybrid_Koppal Steady State Study Report_V01.PDF | K39: 47 | M39: Inverter P for Unity PF, 1.05 pu case. Source: PSS/E output.
A40: 49 | B40: General | C40: Unity PF, Voltage at POI 1.05 pu: Inverter Q(pu) | D40: p.u. | E40: 1.05 | F40: Q_INV | G40: 0 | H40: -1 | I40: 0 | J40: 153.6 MW VEH Green_Hybrid_Koppal Steady State Study Report_V01.PDF | K40: 47 | M40: Inverter Q for Unity PF, 1.05 pu case. Should be ≈0. Source: PSS/E output.
A41: 51 | B41: General | C41: Unity PF, Voltage at POI 1.05 pu: SVG Q(pu) | D41: p.u. | E41: 1.05 | F41: Q_SVG | G41: 0.7 | H41: -1 | I41: 0 | J41: 153.6 MW VEH Green_Hybrid_Koppal Steady State Study Report_V01.PDF | K41: 47 | M41: SVG Q for Unity PF, 1.05 pu case. Source: PSS/E output.
...

Sheet TD Requirement-RE
A1: Technical Data Requirement for Renewable Sources
A3: Sr. No. | B3: Category | C3: Description | D3: Submission Status (Submitted) | E3: Name of File/ Folder Name | F3: Remarks | G3: 📝 Developer Guidance / Explanatory Note
A4: 1 | B4: Technical Details - IBR Unit | C4: Technical Datasheet | D4: Submitted | E4: 3. Datasheets of all the equipment | F4: Submitted
A5: 2 | B5: Technical Details - IBR Unit | C5: Reactive Power Capability Curve (PQ, VQ curve) | D5: Submitted | E5: 8. IBR PQ Capability Curve 9. IBR Power Curve (Speed and Irradiance) | F5: Submitted
A6: 3 | B6: Technical Details - IBR Unit | C6: Temperature Derating PQ Curve | D6: Submitted | E6: 11. IBR Temperature Derating | F6: Submitted
A7: 4 | B7: Technical Details - IBR Unit | C7: Operator Manual of IBR unit(s) | D7: Submitted | E7: 12. Single Machines PSSE model and Benchmarking reports 13. Single Machines PSCAD model and Benchmarking reports | F7: Submitted
A8: 5 | B8: Technical Details - IBR Unit | C8: Proposed Protection Settings of IBR unit (in accordance with Grid-India's FTE&I procedure) | D8: Submitted | E8: 5. Controller and Protection Settings | F8: Submitted
A9: 6 | B9: Technical Details - IBR Unit | C9: Actual Protection Settings of IBR unit (in accordance with Grid-India's FTE&I procedure) | D9: Submitted | F9: Submitted
A10: 7 | B10: Single Line Diagram | C10: RE Pooling Station Switchyard (should include 220 kV, 33kV, IBR level SLD) | D10: Submitted | E10: 2. SLDs | F10: Submitted
A11: 8 | B11: Single Line Diagram | C11: Proposed Geographical SLD (shall comprise lengths, location of IBRs, conductor type, rating) | D11: Submitted | E11: H.4-Wind\H.4.4-Transmission Line\H.4.4.1-33kV Transmission Line Route Layout | F11: Submitted
A12: 9 | B12: Equipment details | C12: Technical Datasheet of IBR unit transformer (IDT) | D12: Submitted | E12: 3. Datasheets of all the equipment\H.3-Solar\H.3.4-Inverter Duty Transformer GA GTP | F12: Submitted | G12: Upload manufacturer-provided technical datasheets. Ensure documents are in English and cover ratings, performance curves, and protection settings.
A13: 10 | B13: Equipment details | C13: Nameplate of the IBR unit transformer | D13: Submitted | E13: 3. Datasheets of all the equipment\H.4-Wind\H.4.2-WTG Transformer GA GTP & Schematics | F13: Submitted | G13: Upload manufacturer-provided technical datasheets. Ensure documents are in English and cover ratings, performance curves, and protection settings.
A14: 11 | B14: Equipment details | C14: Technical Datasheet of Power transformer | D14: Submitted | E14: 3. Datasheets of all the equipment\H.5-PSS\H.5.2-Power Transformer | F14: Submitted | G14: Upload manufacturer-provided technical datasheets. Ensure documents are in English and cover ratings, performance curves, and protection settings.
A15: 12 | B15: Equipment details | C15: Nameplate of the Power transformer | D15: Submitted | E15: 3. Datasheets of all the equipment\H.5-PSS\H.5.2-Power Transformer | F15: Submitted | G15: Upload manufacturer-provided technical datasheets. Ensure documents are in English and cover ratings, performance curves, and protection settings.
A16: 13 | B16: Equipment details | C16: Technical Datasheet of cables | D16: Submitted | E16: 3. Datasheets of all the equipment\H.3-Solar\H.3.5-CablesTD_Doc_013.pdf, 3. Datasheets of all the equipment\H.4-Wind\H.4.3-LT 3.3kV Cable GTP (WTG to USS Trafo) | F16: Submitted | G16: Upload manufacturer-provided technical datasheets. Ensure documents are in English and cover ratings, performance curves, and protection settings.
A17: 14 | B17: Equipment details | C17: Technical Datasheet of overhead conductors | D17: Submitted | E17: 3. Datasheets of all the equipment\H.3-Solar\H.3.6-Transmission Line\H.3.6.2-33kV Transmission Line Conductor GTP (Solar), 3. Datasheets of all the equipment\H.4-Wind\H.4.4-Transmission Line\Transmission Line Conductor GTP (Wind), 28. Miscellaneous\Annexure-A\Annexure-A.2-220kV Transmission line Conductor GTP, | F17: Submitted | G17: Upload manufacturer-provided technical datasheets. Ensure documents are in English and cover ratings, performance curves, and protection settings.
A18: 15 | B18: Equipment details | C18: Power Plant Controller (PPC)_MASTER | D18: Submitted | E18: 7. PPC PSCAD User manual | F18: Submitted | G18: Upload manufacturer-provided technical datasheets. Ensure documents are in English and cover ratings, performance curves, and protection settings.
A19: 16 | B19: Equipment details | C19: PPC Model & Make | D19: Submitted | F19: Submitted | G19: Upload manufacturer-provided technical datasheets. Ensure documents are in English and cover ratings, performance curves, and protection settings.
A20: 17 | B20: Equipment details | C20: Technical Datasheet of PPC | D20: Submitted | E20: 6. PPC Philosophy\EIT PPC Controller Datasheet | F20: Submitted | G20: Upload manufacturer-provided technical datasheets. Ensure documents are in English and cover ratings, performance curves, and protection settings.
A21: 18 | B21: Equipment details | C21: Functional description of the PPC and technical functionality document | D21: Submitted | E21: H.5-PSS\H.5.11-PPC | F21: Submitted | G21: Upload manufacturer-provided technical datasheets. Ensure documents are in English and cover ratings, performance curves, and protection settings.
A22: 19 | B22: Equipment details | C22: Operator manual of PPC | D22: Submitted | E22: H.5-PSS\H.5.11-PPC | F22: Submitted | G22: Upload manufacturer-provided technical datasheets. Ensure documents are in English and cover ratings, performance curves, and protection settings.
A23: 20 | B23: Equipment details | C23: Proposed protection setting and control mode of PPC | D23: Submitted | E23: 5. Controller and Protection Settings\4 PPC | F23: Submitted | G23: Upload manufacturer-provided technical datasheets. Ensure documents are in English and cover ratings, performance curves, and protection settings.
A24: 21 | B24: Equipment details | C24: Power Plant Controller (PPC)_SLAVE (if applicable) | D24: Submitted | E24: NA | F24: Submitted | G24: Upload manufacturer-provided technical datasheets. Ensure documents are in English and cover ratings, performance curves, and protection settings.
A25: 22 | B25: Equipment details | C25: PPC Model & Make | D25: Submitted | E25: NA | F25: Submitted | G25: Upload manufacturer-provided technical datasheets. Ensure documents are in English and cover ratings, performance curves, and protection settings.
A26: 23 | B26: Equipment details | C26: Technical Datasheet of PPC | D26: Submitted | E26: NA | F26: Submitted | G26: Upload manufacturer-provided technical datasheets. Ensure documents are in English and cover ratings, performance curves, and protection settings.
A27: 24 | B27: Equipment details | C27: Functional description of the PPC and technical functionality document | D27: Submitted | E27: NA | F27: Submitted | G27: Upload manufacturer-provided technical datasheets. Ensure documents are in English and cover ratings, performance curves, and protection settings.
A28: 25 | B28: Equipment details | C28: Operator manual of PPC | D28: Submitted | E28: NA | F28: Submitted | G28: Upload manufacturer-provided technical datasheets. Ensure documents are in English and cover ratings, performance curves, and protection settings.
A29: 26 | B29: Equipment details | C29: Proposed protection setting and control mode of PPC | D29: Submitted | E29: NA | F29: Submitted | G29: Upload manufacturer-provided technical datasheets. Ensure documents are in English and cover ratings, performance curves, and protection settings.
A30: 27 | B30: Equipment details | C30: Technical Details of SVG | D30: Submitted | E30: 3. Datasheets of all the equipment\H.5-PSS\H.5.1-SVG | F30: Submitted | G30: Upload manufacturer-provided technical datasheets. Ensure documents are in English and cover ratings, performance curves, and protection settings.
A31: 28 | B31: Equipment details | C31: Technical Datasheet of SVG | D31: Submitted | E31: 3. Datasheets of all the equipment\H.5-PSS\H.5.1-SVG | F31: Submitted | G31: Upload manufacturer-provided technical datasheets. Ensure documents are in English and cover ratings, performance curves, and protection settings.
... A33: 30 | B33: Equipment details | C33: Operator Manual of the SVG | D33: Submitted | E33: 12. Single Machines PSSE model and Benchmarking reports\3 SVG | F33: Submitted | G33: Upload manufacturer-provided Operational Manual. Ensure documents are in English and cover ratings, performance curves, and protection settings.
A34: 31 | B34: Equipment details | C34: Nameplate of SVG | D34: Submitted | E34: 3. Datasheets of all the equipment\H.5-PSS\H.5.1-SVG | F34: Submitted
A35: 32 | B35: Equipment details | C35: Line Length | D35: Submitted | E35: H.4-Wind\H.4.4-Transmission Line\H.4.4.1-33kV Transmission Line Route Layout | F35: Submitted
A36: 33 | B36: Certification & Unit level testing to be furnished by the entity | C36: Type Certification | D36: Submitted | E36: 4. IBR EvaluationType Test Reports and SoC | F36: Submitted | G36: These are type test / certification reports from accredited labs. For each test, attach the full test report PDF.
A37: 34 | B37: Certification & Unit level testing to be furnished by the entity | C37: Type Certificate of single WTG Unit(s) | D37: Submitted | E37: 4. IBR EvaluationType Test Reports and SoC\2 WTG | F37: Submitted | G37: These are type test / certification reports from accredited labs. For each test, attach the full test report PDF.
A38: 35 | B38: Certification & Unit level testing to be furnished by the entity | C38: Type Test Report for Inverter / WTG (Tests to be covered as per CEA Connectivity Standards) | D38: Submitted | E38: 4. IBR EvaluationType Test Reports and SoC\2 WTG | F38: Submitted | G38: These are type test / certification reports from accredited labs. For each test, attach the full test report PDF.
A39: 36 | B39: Certification & Unit level testing to be furnished by the entity | C39: Harmonics | D39: Submitted | E39: 4. IBR EvaluationType Test Reports and SoC | F39: Submitted | G39: These are type test / certification reports from accredited labs. For each test, attach the full test report PDF.
A40: 37 | B40: Certification & Unit level testing to be furnished by the entity | C40: DC Current Injection | D40: Submitted | E40: 4. IBR EvaluationType Test Reports and SoC | F40: Submitted | G40: These are type test / certification reports from accredited labs. For each test, attach the full test report PDF.
A41: 38 | B41: Certification & Unit level testing to be furnished by the entity | C41: Flicker | D41: Submitted | E41: 4. IBR EvaluationType Test Reports and SoC | F41: Submitted | G41: These are type test / certification reports from accredited labs. For each test, attach the full test report PDF.
A42: 39 | B42: Certification & Unit level testing to be furnished by the entity | C42: PQ Capability Test | D42: Submitted | E42: 4. IBR EvaluationType Test Reports and SoC | F42: Submitted | G42: These are type test / certification reports from accredited labs. For each test, attach the full test report PDF.
...

Sheet Power Quality
A1: Power Quality Requirement for Renewable Energy Sources
A3: Sl No | B3: Category | C3: Description | D3: Harmonic Category | E3: Unit | F3: Value Observed | G3: Limit | H3: Ref Document-1 | I3: Page number of the document-Ref-1 | J3: Remarks | K3: 📝 Developer Guidance / Explanatory Note
A4: 1 | B4: General | C4: Short circuit level received input from CTU/RLDC | D4: SCMVA_grid | E4: MVA | F4: 16893.53 | G4: NA | H4: 26. Technical note and explanations by developers & OEMs\Mail Ref_Actual shot circuit MVA of Koppal-II | I4: 1 | J4: Short circuit data from CTU | K4: Short Circuit Level (SCL) at POI in MVA. Obtain this value from CTU/RLDC via a formal letter or email. Do NOT estimate. Enter the value from CTU SCL communication.
A5: 2 | B5: General | C5: Thevenin Impedance Received from CTU/RLDC | D5: Zgrid | E5: Ohm | F5: 2.865 | G5: NA | H5: 26. Technical note and explanations by developers & OEMs\Mail Ref_Actual shot circuit MVA of Koppal-II | I5: 1 | J5: Short circuit data from CTU | K5: Thevenin impedance at POI received from CTU/RLDC. Enter in complex form: 'R+jX Ohm'. Example: '3+4J'. Source: CTU SCL communication letter or email. Required for harmonic load flow setup.
A6: 3 | B6: Harmonics | C6: Harmonic current injections are as per test report (PSCAD model) | E6: Y/N | F6: Yes | G6: NA | H6: 20. PSCAD Power Quality Report\Power_Quality_Report_VEH_Rev_B | I6: 8 | J6: PSCAD model harmonics within limits | K6: Verify that harmonic current injections used in the PSCAD model match the type test report data for each 10% power bin. Enter 'Yes' if verified, 'No' if not. Attach Harmonic Study Report.
A7: 4 | B7: Harmonics | C7: Harmonic load flow achieved or solved | E7: Y/N | F7: Yes | G7: NA | H7: 20. PSCAD Power Quality Report\Power_Quality_Report_VEH_Rev_B | I7: 20 | J7: Harmonic LF converged | K7: Confirm the harmonic load flow simulation converged (solved). Enter 'Yes' if converged, 'No' if diverged. If 'No', revise model and re-run. Attach final converged study report.
A8: 5 | B8: Harmonics | C8: Unit level test report contain harmonic spectrum for each 10% active power bin | E8: Y/N | F8: Yes | G8: NA | H8: Type Test Report.pdf | I8: 22 | J8: Spectra for each 10% power bin | K8: Confirm the unit-level type test report contains harmonic spectrum (current THD at each harmonic order) for each 10% power bin from 10% to 100%. Enter 'Yes' or 'No'. Mandatory per CEA Connectivity Standards.
A9: 6 | B9: Harmonics | C9: Maximum Harmonic Current Distortion (TDD) | D9: TDD (max) | E9: % | F9: 1.179 | G9: 0.015 | H9: 20. PSCAD Power Quality Report\Power_Quality_Report_VEH_Rev_B | I9: 29 | J9: Below 1.5% limit ✓ | K9: Enter the maximum Total Demand Distortion (TDD) value observed in harmonic load flow study as a percentage. Limit: ≤1.5%. Example: 1.1%. Source: PSCAD harmonic study report. Must be below limit.
A10: 7 | B10: Harmonics | C10: TDD- 2, 4, 6 : Maximum Observed Among All Cases | D10: h = 2,4,6 | E10: % | F10: 0.003945 | G10: 0.005 | H10: 20. PSCAD Power Quality Report\Power_Quality_Report_VEH_Rev_B | I10: 32 | J10: Below 0.5% limit ✓ | K10: TDD for even harmonics (orders 2, 4, 6). Enter value in %. Limit: ≤0.5%. Source: Harmonic Study Report.
A11: 8 | B11: Harmonics | C11: TDD - 2≤h<11(except 2, 4 & 6) : Maximum Observed Among All Cases | D11: 2< h <11 (except for 2,4,6) | E11: % | F11: 0.009431 | G11: 0.01 | H11: 20. PSCAD Power Quality Report\Power_Quality_Report_VEH_Rev_B | I11: 32 | J11: Below 1.0% limit ✓ | K11: TDD for harmonic orders 2 ≤ h < 11. Enter value in %. CEA Limit: ≤1.0%. Source: Harmonic Study Report. Example: 0.7%.
A12: 9 | B12: Harmonics | C12: TDD - 11≤h<17 : Maximum Observed Among All Cases | D12: 11≤h<17 | E12: % | F12: 0.000735 | G12: 0.005 | H12: 20. PSCAD Power Quality Report\Power_Quality_Report_VEH_Rev_B | I12: 32 | J12: Below 0.5% limit ✓ | K12: TDD for harmonic orders 11 ≤ h < 17. Enter value in %. CEA Limit: ≤0.5%. Source: Harmonic Study Report. Example: 0.3%.
A13: 10 | B13: Harmonics | C13: TDD - 17≤h<23 : Maximum Observed Among All Cases | D13: 17≤h<23 | E13: % | F13: 0.00269 | G13: 0.0038 | H13: 20. PSCAD Power Quality Report\Power_Quality_Report_VEH_Rev_B | I13: 32 | J13: Below 0.38% limit ✓ | K13: TDD for harmonic orders 17 ≤ h < 23. Enter value in %. CEA Limit: ≤0.38%. Source: Harmonic Study Report. Example: 0.22%.
A14: 11 | B14: Harmonics | C14: TDD - 23≤h<35 : Maximum Observed Among All Cases | D14: 23≤h<35 | E14: % | F14: 0.000851 | G14: 0.0015 | H14: 20. PSCAD Power Quality Report\Power_Quality_Report_VEH_Rev_B | I14: 32 | J14: Below 0.1% limit ✓ | K14: TDD for harmonic orders 23 ≤ h < 35. Enter value in %. CEA Limit: ≤0.15%. Source: Harmonic Study Report. Example: 0.06%.
A15: 12 | B15: Harmonics | C15: TDD - 35≤h<50 : Maximum Observed Among All Cases | D15: 35≤h<50 | E15: % | F15: 9.92e-05 | G15: 0.001 | H15: 20. PSCAD Power Quality Report\Power_Quality_Report_VEH_Rev_B | I15: 32 | J15: h>=35 band – no limit defined | K15: TDD for harmonic orders 35 ≤ h < 50. Enter value in %. CEA Limit: ≤0.10%. Source: Harmonic Study Report. Typically very small (< 0.05%).
A16: 13 | B16: DC Injection | C16: DC Injection Current Observed : Maximum Observed Among All Cases | D16: h = 0 (DC) | E16: % | F16: 0.00024 | G16: 0.005 | H16: 20. PSCAD Power Quality Report\Power_Quality_Report_VEH_Rev_B | I16: 9 | J16: Below 0.5% limit ✓ | K16: DC Current Injection as a percentage of rated AC current at POI. CEA Limit: ≤0.5%. Verify from type test report or simulation. Example: 0.18%. Source: DC Injection Test Report.
A17: 14 | B17: Flicker | C17: Flicker - Short Term Limit | D17: Flicker (St) | E17: NA | F17: 0.001 | G17: 0.01 | H17: 20. PSCAD Power Quality Report\Power_Quality_Report_VEH_Rev_B | I17: 11 | J17: Pst = 0.52 ≤ 0.8 ✓ | K17: Short-Term Flicker severity index (Pst) at POI. CEA Limit: Pst ≤ 1.0.Source: Flicker measurement or calculation/simulation report.
A18: 15 | B18: Flicker | C18: Flicker - Long Term Limit | D18: Flicker (Lt) | E18: NA | F18: 0.001 | G18: 0.008 | H18: 20. PSCAD Power Quality Report\Power_Quality_Report_VEH_Rev_B | I18: 11 | J18: Plt = 0.41 ≤ 0.6 ✓ | K18: Long-Term Flicker severity index (Plt) at POI. CEA Limit: Plt ≤ 0.8. Typical value: 0.3–0.5. Source: Flicker test/simulation report.
A19: 16 | B19: Voltage Unbalance | C19: Voltage Unbalance as per IEC 61000-4-30 | E19: % | F19: 0.7 | G19: 1.5 | H19: Voltage Measurement Report.pdf | I19: 7 | J19: ≤1% per IEC 61000-4-30 ✓ | K19: Voltage Unbalance at POI measured per IEC 61000-4-30. CEA Limit: ≤1.5% (typically ≤1.0% per IEC). Enter measured/simulated value. Source: Power Quality measurement report.
A20: 17 | B20: Harmonics | C20: Inter-harmonic measurement data submitted (OPTIONAL) | D20: h = 0.5,1.5,2.5,3.5,…. | E20: Y/N | F20: Submitted | H20: Inter-harmonic Report | I20: 3 | J20: Optional – voluntarily submitted | K20: Optional submission. If inter-harmonic measurement data is available from type test, submit the report. Enter 'Submitted' if provided, or 'Not Submitted' if not measured. No mandatory limit.
A24: The Applicant is required to fill in yellow-highlighted cells only. All remaining fields are system-locked and pre-populated for reference.

Sheet Dynamic Data-RE
A1: Dynamics Simulation Data for Renewable Energy Sources
A3: Sl No | B3: Category | C3: Voltage Dip/Swell Depth | D3: Description | E3: Notation of Measured Electrical Quantities | F3: Unit / Data Type | G3: Value Observed (PSSE) | H3: Value Observed (PSCAD) | I3: Lower Limit(Mag) | J3: Upper Limit(Mag) | K3: Document Name | L3: Page number of the document | M3: 📝 Developer Guidance / Explanatory Note | N3: Visual Representation
A4: 1 | B4: LVRT/HVRT | D4: Is tripping of Inverter/WTG/PCS/SVG observed during in any LVRT/HVRT case? | F4: Yes/No | G4: No | H4: No | I4: NA | J4: NA | K4: Annexure PSSE Model Study Response for Hybrid Operation.pdf | M4: Dynamic check: Did any inverter/WTG/SVG trip (disconnect) during LVRT or HVRT simulation? Expected answer: 'No'. If 'Yes', identify the cause (protection settings, model error) and fix before submission.
A5: 2 | B5: General/Unit Level | D5: Are Id(direct-axis current) & Iq (quadrature-axis current) are as per equipment Fault Ride-Through(FRT) logic? | F5: Yes/No | G5: No | H5: No | I5: NA | J5: NA | K5: Annexure PSSE Model Study Response for Hybrid Operation.pdf | M5: Verify that Id (direct-axis current) and Iq (quadrature-axis current) responses in simulation match the FRT control logic specified in OEM firmware. Expected: 'Yes'. Source: PSSE & PSCAD Dynamics Report.
A6: 3 | B6: General/Unit Level | D6: Parameters as per Firmware/Benchmarking/Simulations are Aligned | F6: Yes/No | G6: No | H6: No | I6: NA | J6: NA | K6: Annexure PSSE Model Study Response for Hybrid Operation.pdf | M6: Confirm that model parameters (K-factor, time constants, thresholds) are consistent between firmware documentation, benchmarking reports, and simulation models (PSS/E and PSCAD). Expected: 'Yes'. Discrepancies must be resolved.
A7: 4 | B7: LVRT/HVRT | C7: V=15% | D7: Incremental Reactive Current Injection of Inverter - Minimum among all aggregated inverters Voltage Dip 0.15 pu | 100% P | Symmetrical | Solar | E7: Del_Iq | F7: p.u. | G7: 0.101666 | H7: 0.5898 | I7: 0 | J7: =1 -> 1 | K7: Annexure PSSE Model Study Response for Hybrid Operation.pdf | L7: 122 | M7: Incremental Reactive Current injection (ΔIq in p.u.) by the inverter during 0.15 p.u. voltage dip (severe LVRT, 3-phase symmetrical fault), at 100% active power dispatch. Lower limit: >0.001 p.u. (must show reactive support). Source: PSS/E dynamics run, LVRT test case.
A8: 5 | B8: LVRT/HVRT | C8: V=15% | D8: Total Reactive Current support - Minimum among all inverters Voltage Dip 0.15 pu | 100% P | Symmetrical | Solar | E8: Iq_f = Iq_pref + Del_Iq | F8: p.u. | G8: 0.336925 | H8: =0.0018+0.5898 -> 0.5916 | I8: -1 | J8: 1 | K8: Annexure PSSE Model Study Response for Hybrid Operation.pdf | L8: 122 | M8: Total reactive current at the inverter terminal during the 0.15 pu LVRT case. Addition of pre-fault current and incremental current.Enter minimum value amongst the all feeders/inverters.
A9: 6 | B9: LVRT/HVRT | C9: V=15% | D9: Active Current of Inverter - Maximum among all inverters Voltage Dip 0.15 pu | 100% P | Symmetrical | Solar | E9: Id_INV_max | F9: p.u. | G9: 0.869635 | H9: 0.2744 | I9: 0 | J9: 1 | K9: Annexure PSSE Model Study Response for Hybrid Operation.pdf | L9: 122 | M9: Active current (Id in p.u.) of inverter during the same 0.15 pu LVRT case. Active current may reduces during LVRT to prioritize reactive support. Lower limit: >0.001. Source: PSS/E dynamics report.
A10: 7 | B10: LVRT/HVRT | C10: V=15% | D10: Total Apparant Current of Inverter - Maximum among all inverters Voltage Dip 0.15 pu | 100% P | Symmetrical | Solar | E10: Irms_3PH_INV_max | F10: p.u. | G10: 0.93711101 | H10: 0.2747 | I10: 0 | J10: 1 | K10: Annexure PSSE Model Study Response for Hybrid Operation.pdf | L10: 122 | M10: Total Apparant current (I in p.u.) of inverter during the same 0.15 pu LVRT case. Apparent current should be close to 1. Source: PSS/E dynamics report.
A11: 8 | B11: LVRT/HVRT | C11: V=15% | D11: Active Power Recovery within 1 second of Fault Clearance Voltage Dip 0.15 pu | 100% P | Symmetrical | Solar | E11: P_post_LVRT_1sec | F11: % | G11: 93.2 | H11: 0.269 | I11: 90 | J11: 90 | K11: Annexure PSSE Model Study Response for Hybrid Operation.pdf | L11: 122 | M11: % of pre-fault active power restored within 1 second of fault clearance (LVRT 0.15 pu, 100% P, symmetrical). CEA requirement: ≥90% recovery within 1 second. Source: PSS/E post-fault response curve.
A12: 9 | B12: LVRT/HVRT | C12: V=15% | D12: Incremental Reactive Current Injection of WTG Voltage Dip 0.15 pu | 100% P | Symmetrical | WTG | E12: Del_Iq | F12: p.u. | G12: 1.029935 | H12: 0.8673 | I12: 0 | J12: 1 | K12: Annexure PSSE Model Study Response for Hybrid Operation.pdf | L12: 124 | M12: Incremental Reactive Current injection (ΔIq in p.u.) by the WTG during 0.15 p.u. voltage dip (severe LVRT, 3-phase symmetrical fault), at 100% active power dispatch. Lower limit: >0.001 p.u. (must show reactive support). Source: PSS/E dynamics run, LVRT test case.
A13: 10 | B13: LVRT/HVRT | C13: V=15% | D13: Total Reactive Current support of WTG Voltage Dip 0.15 pu | 100% P | Symmetrical | WTG | E13: Iq_f = Iq_pref + Del_Iq | F13: p.u. | G13: 1.1 | H13: =0.0027+0.8673 -> 0.87 | I13: -1 | J13: 1 | K13: Annexure PSSE Model Study Response for Hybrid Operation.pdf | L13: 124 | M13: Total reactive current at the WTG terminal during the 0.15 pu LVRT case. Addition of pre-fault current and incremental current.
